Workbook

Sheet Cleaned_Data
A1: student_id | B1: branch | C1: track | D1: gender | E1: age | F1: study_hours_week | G1: commute_minutes | H1: sleep_hours | I1: projects_submitted | J1: satisfaction_1to5 | K1: has_laptop | L1: transport | M1: pets_at_home | N1: favorite_sport | O1: final_score | P1: num_id
A2: ITI-1031 | B2: cairo | C2: data science | D2: m | E2: 21 | F2: 16.5 | G2: 34.1 | H2: 5.5 | I2: 2 | J2: 3 | K2: yes | L2: car | M2: 0 | N2: swimming | O2: 79.3 | P2: 1031
A3: ITI-1117 | B3: assiut | C3: data science | D3: f | E3: 29 | F3: 25.1 | G3: 5 | H3: 6.6 | I3: 3 | J3: 4 | K3: yes | L3: metro | M3: 1 | N3: football | O3: 91.7 | P3: 1117
A4: ITI-1080 | B4: cairo | C4: data science | D4: m | E4: 25 | F4: 14.1 | G4: 73.2 | H4: 7.7 | I4: 0 | J4: 4 | K4: yes | L4: bus | M4: 0 | O4: 79.3 | P4: 1080
A5: ITI-1128 | B5: cairo | C5: web development | D5: f | E5: 25 | F5: 5 | G5: 13.7 | H5: 6.3 | I5: 2 | J5: 4 | K5: yes | L5: metro | M5: 1 | O5: 90.6 | P5: 1128
A6: ITI-1197 | B6: menoufia | C6: web development | D6: m | E6: 25 | F6: 19.9 | G6: 17.2 | H6: 6.9 | I6: 3 | J6: 3 | K6: no | L6: car | M6: 0 | O6: 86.8 | P6: 1197
A7: ITI-1138 | B7: cairo | C7: ui/ux | D7: m | E7: 22 | F7: 8.5 | G7: 29.6 | H7: 5.2 | I7: 4 | J7: 2 | K7: yes | L7: microbus | M7: 1 | N7: running | O7: 59.1 | P7: 1138
A8: ITI-1210 | B8: cairo | C8: data science | D8: m | E8: 21 | F8: 20.4 | G8: 56.1 | H8: 6.2 | I8: 3 | J8: 5 | K8: yes | L8: bus | M8: 0 | N8: football | O8: 92.5 | P8: 1210
A9: ITI-1046 | B9: cairo | C9: data science | D9: f | E9: 23 | F9: 14 | G9: 51.7 | H9: 7.4 | I9: 3 | J9: 3 | K9: yes | L9: bus | M9: 3 | N9: football | O9: 72.6 | P9: 1046
A10: ITI-1159 | B10: assiut | C10: data science | D10: m | E10: 20 | F10: 17.6 | G10: 21.8 | H10: 6.1 | I10: 5 | J10: 4 | K10: yes | L10: walk | M10: 1 | N10: swimming | O10: 88.6 | P10: 1159
A11: ITI-1248 | B11: alexandria | C11: data science | D11: m | E11: 22 | F11: 18.7 | G11: 15 | H11: 7.3 | I11: 4 | J11: 4 | K11: no | L11: microbus | M11: 0 | N11: basketball | O11: 84.9 | P11: 1248
A12: ITI-1184 | B12: mansoura | C12: web development | D12: f | E12: 23 | F12: 12.2 | G12: 58.2 | H12: 7.3 | I12: 7 | J12: 3 | K12: yes | L12: microbus | M12: 2 | O12: 71.9 | P12: 1184
A13: ITI-1042 | B13: cairo | C13: data science | D13: m | E13: 27 | F13: 21.9 | G13: 22.8 | H13: 6.7 | I13: 6 | J13: 5 | K13: yes | L13: bus | M13: 0 | N13: basketball | O13: 87.7 | P13: 1042
A14: ITI-1228 | B14: alexandria | C14: web development | D14: f | E14: 20 | F14: 16.526721 | G14: 15.7 | H14: 6.1 | I14: 2 | J14: 5 | K14: yes | L14: car | M14: 0 | N14: football | O14: 55.6 | P14: 1228
A15: ITI-1083 | B15: cairo | C15: data science | D15: m | E15: 23 | F15: 12.3 | G15: 39.2 | H15: 6.3 | I15: 5 | J15: 5 | K15: yes | L15: bus | M15: 0 | N15: running | O15: 78.6 | P15: 1083
A16: ITI-1166 | B16: alexandria | C16: web development | D16: m | E16: 26 | F16: 13.1 | G16: 63.8 | H16: 7.9 | I16: 1 | J16: 5 | K16: yes | L16: bus | M16: 0 | O16: 74.3 | P16: 1166
A17: ITI-1195 | B17: mansoura | C17: ui/ux | D17: f | E17: 25 | F17: 14.7 | G17: 13.6 | H17: 6.9 | I17: 4 | J17: 3 | K17: yes | L17: bus | M17: 0 | O17: 77.2 | P17: 1195
A18: ITI-1227 | B18: alexandria | C18: web development | D18: m | E18: 22 | F18: 16.6 | G18: 59.1 | H18: 7.5 | I18: 2 | J18: 3 | K18: yes | L18: bus | M18: 0 | N18: basketball | O18: 66.8 | P18: 1227
A19: ITI-1147 | B19: cairo | C19: data science | D19: f | E19: 20 | F19: 18.6 | G19: 44.3 | H19: 7 | I19: 6 | J19: 2 | K19: yes | L19: metro | M19: 0 | N19: football | O19: 83.7 | P19: 1147
A20: ITI-1105 | B20: alexandria | C20: web development | D20: f | E20: 25 | F20: 25.9 | G20: 22.4 | H20: 7.1 | I20: 4 | J20: 3 | K20: yes | L20: bus | M20: 0 | N20: running | O20: 87.4 | P20: 1105
A21: ITI-1061 | B21: assiut | C21: data science | D21: m | E21: 23 | F21: 24.3 | G21: 5 | H21: 6 | I21: 5 | J21: 5 | K21: no | L21: metro | M21: 1 | N21: football | O21: 91.6 | P21: 1061
A22: ITI-1222 | B22: cairo | C22: data science | D22: m | E22: 21 | F22: 21.2 | G22: 30.3 | H22: 7.2 | I22: 6 | J22: 5 | K22: yes | L22: walk | M22: 0 | N22: football | O22: 90 | P22: 1222
A23: ITI-1109 | B23: menoufia | C23: data science | D23: m | E23: 23 | F23: 9.5 | G23: 43.9 | H23: 6.6 | I23: 3 | J23: 5 | K23: yes | L23: microbus | M23: 1 | N23: basketball | O23: 77 | P23: 1109
A24: ITI-1047 | B24: cairo | C24: data science | D24: f | E24: 22 | F24: 6.4 | G24: 17.1 | H24: 7 | I24: 4 | J24: 3 | K24: yes | L24: metro | M24: 0 | N24: football | O24: 66.9 | P24: 1047
A25: ITI-1043 | B25: cairo | C25: ui/ux | D25: f | E25: 24 | F25: 13.7 | G25: 111.7 | H25: 6.9 | I25: 1 | J25: 3 | K25: yes | L25: bus | M25: 2 | O25: 69.4 | P25: 1043
A26: ITI-1186 | B26: cairo | C26: embedded systems | D26: m | E26: 21 | F26: 18.3 | G26: 66.4 | H26: 8.7 | I26: 4 | J26: 3 | K26: yes | L26: bus | M26: 0 | O26: 85.7 | P26: 1186
A27: ITI-1010 | B27: menoufia | C27: data science | D27: f | E27: 24 | F27: 25.7 | G27: 10.8 | H27: 6.1 | I27: 3 | J27: 4 | K27: yes | L27: walk | M27: 2 | O27: 80.3 | P27: 1010
A28: ITI-1023 | B28: menoufia | C28: web development | D28: m | E28: 24 | F28: 21.5 | G28: 8.4 | H28: 7 | I28: 7 | J28: 5 | K28: yes | L28: bus | M28: 1 | O28: 91.7 | P28: 1023
A29: ITI-1200 | B29: alexandria | C29: web development | D29: m | E29: 23 | F29: 16.526721 | G29: 35.2 | H29: 6.6 | I29: 3 | J29: 3 | K29: yes | L29: walk | M29: 1 | N29: football | O29: 75.3 | P29: 1200
A30: ITI-1110 | B30: mansoura | C30: web development | D30: f | E30: 20 | F30: 9.3 | G30: 31 | H30: 6.7 | I30: 1 | J30: 4 | K30: no | L30: car | M30: 0 | N30: running | O30: 74.6 | P30: 1110
A31: ITI-1025 | B31: mansoura | C31: data science | D31: m | E31: 20 | F31: 17.7 | G31: 43.8 | H31: 6.8 | I31: 7 | J31: 4 | K31: yes | L31: walk | M31: 0 | N31: swimming | O31: 77.2 | P31: 1025
A32: ITI-1114 | B32: mansoura | C32: data science | D32: f | E32: 29 | F32: 18.8 | G32: 16.2 | H32: 5.7 | I32: 0 | J32: 3 | K32: no | L32: metro | M32: 1 | N32: running | O32: 76.6 | P32: 1114
A33: ITI-1069 | B33: cairo | C33: ui/ux | D33: m | E33: 24 | F33: 16.5 | G33: 83 | H33: 8.1 | I33: 2 | J33: 4 | K33: yes | L33: metro | M33: 0 | O33: 90 | P33: 1069
A34: ITI-1225 | B34: mansoura | C34: data science | D34: m | E34: 25 | F34: 17.9 | G34: 12.2 | H34: 6.3 | I34: 3 | J34: 4 | K34: yes | L34: bus | M34: 0 | N34: swimming | O34: 84.2 | P34: 1145
A35: ITI-1253 | B35: cairo | C35: ui/ux | D35: f | E35: 28 | F35: 9.8 | G35: 27.2 | H35: 7.8 | I35: 2 | J35: 2 | K35: yes | L35: microbus | M35: 0 | N35: running | O35: 71 | P35: 1225
A36: ITI-1007 | B36: alexandria | C36: embedded systems | D36: m | E36: 24 | F36: 19.7 | G36: 31.9 | H36: 7.6 | I36: 1 | J36: 4 | K36: yes | L36: bus | M36: 0 | N36: running | O36: 90.3 | P36: 1253
A37: ITI-1121 | B37: cairo | C37: data science | D37: f | E37: 23 | F37: 12.7 | G37: 11.6 | H37: 6 | I37: 5 | J37: 2 | K37: no | L37: microbus | M37: 0 | N37: football | O37: 78.3 | P37: 1007
A38: ITI-1068 | B38: menoufia | C38: data science | D38: m | E38: 25 | F38: 16.6 | G38: 44.1 | H38: 6.6 | I38: 3 | J38: 5 | K38: no | L38: bus | M38: 0 | N38: football | O38: 79.5 | P38: 1121
A39: ITI-1120 | B39: assiut | C39: data science | D39: f | E39: 21 | F39: 14.1 | G39: 18.5 | H39: 8.1 | I39: 3 | J39: 5 | K39: yes | L39: car | M39: 0 | N39: football | O39: 71.9 | P39: 1068
A40: ITI-1119 | B40: cairo | C40: embedded systems | D40: f | E40: 25 | F40: 2 | G40: 50.1 | H40: 8 | I40: 3 | J40: 4 | K40: no | L40: bus | M40: 3 | N40: running | O40: 80.2 | P40: 1120
...

Sheet Descriptive Statistics Summary
A1: Part C — Descriptive Statistics Summary
A4: SECTION 1 — Overall Descriptive Statistics(Commute _Minutes)
A5: Measure | B5: Results
A6: N (count of non-blank values) | B6: =COUNT(Cleaned_Data!G2:G250) -> 243
A7: Mean | B7: =AVERAGE(Cleaned_Data!G:G) -> 45.436214
A8: Median | B8: =MEDIAN(Cleaned_Data!G:G) -> 33
A9: Mode | B9: 16.1, 25.9,37,2
A10: Minimum | B10: =MIN(Cleaned_Data!G:G) -> 5
A11: Maximum | B11: =MAX(Cleaned_Data!G:G) -> 256.5
A12: Range (Max − Min) | B12: =256.5 - 5 -> 251.5
A13: Standard Deviation (sample) | B13: =_xlfn.STDEV.S(Cleaned_Data!G:G) -> 40.151769
A14: Q1 (25th percentile) | B14: =_xlfn.QUARTILE.INC(Cleaned_Data!G:G, 1) -> 19.95
A15: Q3 (75th percentile) | B15: =_xlfn.QUARTILE.INC(Cleaned_Data!G:G,3 ) -> 59.2
A16: IQR (Q3 − Q1) | B16: =B15-B14 -> 39.25
A18: SECTION 2 — Branch Summary Table (Commute_minutes)
A20: Branch | B20: Count | C20: Median | D20: Std Dev | E20: Mean
A21: Cairo | B21: =COUNTIFS(Cleaned_Data!$B$2:$B$250, $A21, Cleaned_Data!$G$2:$G$250, "<>") -> 95 | C21: {=MEDIAN(_xlfn._xlws.FILTER(Cleaned_Data!$G$2:$G$250, (Cleaned_Data!$B$2:$B$250=$A21) * (Cleaned_Data!$G$2:$G$250<>"")))} -> 50.1 | D21: {=_xlfn.STDEV.S(_xlfn._xlws.FILTER(Cleaned_Data!$G$2:$G$250, (Cleaned_Data!$B$2:$B$250=$A21) * (Cleaned_Data!$G$2:$G$250<>"")))} -> 45.37435 | E21: =AVERAGEIFS(Cleaned_Data!$G$2:$G$250,Cleaned_Data!$B$2:$B$250,$A21) -> 61.066316
A22: Alexandria | B22: =COUNTIFS(Cleaned_Data!$B$2:$B$250, $A22, Cleaned_Data!$G$2:$G$250, "<>") -> 49 | C22: {=MEDIAN(_xlfn._xlws.FILTER(Cleaned_Data!$G$2:$G$250, (Cleaned_Data!$B$2:$B$250=$A22) * (Cleaned_Data!$G$2:$G$250<>"")))} -> 34.8 | D22: {=_xlfn.STDEV.S(_xlfn._xlws.FILTER(Cleaned_Data!$G$2:$G$250, (Cleaned_Data!$B$2:$B$250=$A22) * (Cleaned_Data!$G$2:$G$250<>"")))} -> 37.095715 | E22: =AVERAGEIFS(Cleaned_Data!$G$2:$G$250,Cleaned_Data!$B$2:$B$250,$A22) -> 43.757143
A23: Menoufia | B23: =COUNTIFS(Cleaned_Data!$B$2:$B$250, $A23, Cleaned_Data!$G$2:$G$250, "<>") -> 30 | C23: {=MEDIAN(_xlfn._xlws.FILTER(Cleaned_Data!$G$2:$G$250, (Cleaned_Data!$B$2:$B$250=$A23) * (Cleaned_Data!$G$2:$G$250<>"")))} -> 25.75 | D23: {=_xlfn.STDEV.S(_xlfn._xlws.FILTER(Cleaned_Data!$G$2:$G$250, (Cleaned_Data!$B$2:$B$250=$A23) * (Cleaned_Data!$G$2:$G$250<>"")))} -> 37.860883 | E23: =AVERAGEIFS(Cleaned_Data!$G$2:$G$250,Cleaned_Data!$B$2:$B$250,$A23) -> 35.666667
A24: Mansoura | B24: =COUNTIFS(Cleaned_Data!$B$2:$B$250, $A24, Cleaned_Data!$G$2:$G$250, "<>") -> 40 | C24: {=MEDIAN(_xlfn._xlws.FILTER(Cleaned_Data!$G$2:$G$250, (Cleaned_Data!$B$2:$B$250=$A24) * (Cleaned_Data!$G$2:$G$250<>"")))} -> 26 | D24: {=_xlfn.STDEV.S(_xlfn._xlws.FILTER(Cleaned_Data!$G$2:$G$250, (Cleaned_Data!$B$2:$B$250=$A24) * (Cleaned_Data!$G$2:$G$250<>"")))} -> 30.719241 | E24: =AVERAGEIFS(Cleaned_Data!$G$2:$G$250,Cleaned_Data!$B$2:$B$250,$A24) -> 31.8575
A25: Assiut | B25: =COUNTIFS(Cleaned_Data!$B$2:$B$250, $A25, Cleaned_Data!$G$2:$G$250, "<>") -> 29 | C25: {=MEDIAN(_xlfn._xlws.FILTER(Cleaned_Data!$G$2:$G$250, (Cleaned_Data!$B$2:$B$250=$A25) * (Cleaned_Data!$G$2:$G$250<>"")))} -> 24 | D25: {=_xlfn.STDEV.S(_xlfn._xlws.FILTER(Cleaned_Data!$G$2:$G$250, (Cleaned_Data!$B$2:$B$250=$A25) * (Cleaned_Data!$G$2:$G$250<>"")))} -> 16.412559 | E25: =AVERAGEIFS(Cleaned_Data!$G$2:$G$250,Cleaned_Data!$B$2:$B$250,$A25) -> 25.906897
F26: The outliers(Rows) | L26: The outliers(Rows)
A27: SECTION 3 — Outlier Fences (1.5×IQR) | E27: Excel Row | F27: Student ID | G27: Branch | H27: Commute (min) | I27: Final Score | K27: Excel Row | L27: Student ID | M27: Branch | N27: Commute (min) | O27: Final Score
A28: Measure | B28: Results | E28: 43 | F28: ITI-1020 | G28: Cairo | H28: 133.7 | I28: 68.1 | K28: 205 | L28: ITI-1132 | M28: Cairo | N28: 191.4 | O28: 74.3
A29: Lower fence (Q1 - 1.5×IQR) | B29: =B14-(1.5*B16) -> -38.925 | E29: 73 | F29: ITI-1113 | G29: Cairo | H29: 120.2 | I29: 80.2 | K29: 229 | L29: ITI-1049 | M29: Cairo | N29: 142.3 | O29: 85.3
A30: Upper fence (Q3 + 1.5×IQR) | B30: =B15+(1.5*B16) -> 118.075 | E30: 95 | F30: ITI-1148 | G30: Cairo | H30: 176 | I30: 70.1
A31: Count of OUTLIERS | B31: =COUNTIF(Cleaned_Data!$G$2:$G$250,">"&B30) -> 14 | E31: 115 | F31: ITI-1086 | G31: Cairo | H31: 200 | I31: 83.7
E32: 117 | F32: ITI-1173 | G32: Cairo | H32: 132 | I32: 81.8
A33: SECTION 4 — Coefficient of Variation (CV = StdDev / Mean × 100) | E33: 134 | F33: ITI-1101 | G33: Cairo | H33: 256.5 | I33: 99
A34: Variable | B34: CV result (%) | E34: 139 | F34: ITI-1151 | G34: Cairo | H34: 154 | I34: 50.4
A35: commute_minutes | B35: =(B13/B7)*100 -> 88.36953 | C35: Commute Minutes | D35: =(B13/B7)*100 -> 88.36953 | E35: 143 | F35: ITI-1231 | G35: Cairo | H35: 126.7 | I35: 69.2
A36: final_score | B36: {=_xlfn.STDEV.S(IFERROR(VALUE(SUBSTITUTE(Cleaned_Data!O2:O250,",",".")),""))/AVERAGE(IFERROR(VALUE(SUBSTITUTE(Cleaned_Data!O2:O250,",",".")),"")) * 100} -> 12.316518 | C36: Final score | D36: {=_xlfn.STDEV.S(IFERROR(VALUE(SUBSTITUTE(Cleaned_Data!O2:O250,",",".")),""))/AVERAGE(IFERROR(VALUE(SUBSTITUTE(Cleaned_Data!O2:O250,",",".")),"")) * 100} -> 12.316518 | E36: 153 | F36: ITI-1063 | G36: Mansoura | H36: 190.2 | I36: 85.6
E37: 157 | F37: ITI-1071 | G37: Menoufia | H37: 209.8 | I37: Missing
A38: SECTION 5 — Distribution Chart | E38: 186 | F38: ITI-1104 | G38: Cairo | H38: 121.4 | I38: 68.5
E39: 194 | F39: ITI-1199 | G39: Alexandria | H39: 238.9 | I39: 76.1

Sheet All Columns
A1: Descriptive Statistics — All Numeric Columns
A3: Variable | B3: N (Count) | C3: Mean | D3: Median | E3: Mode | F3: Std Dev (Sample) | G3: Minimum | H3: Maximum | I3: Range | J3: Q1 | K3: Q3 | L3: IQR | M3: CV (%)
A4: age | B4: =COUNT(Cleaned_Data!E2:E250) -> 249 | C4: =AVERAGE(Cleaned_Data!E2:E250) -> 23.51004 | D4: =MEDIAN(Cleaned_Data!E2:E250) -> 23 | E4: 23 | F4: =_xlfn.STDEV.S(Cleaned_Data!E2:E250) -> 2.2181663 | G4: =MIN(Cleaned_Data!E2:E250) -> 20 | H4: =MAX(Cleaned_Data!E2:E250) -> 30 | I4: =H4-G4 -> 10 | J4: =_xlfn.QUARTILE.INC(Cleaned_Data!E2:E250,1) -> 22 | K4: =_xlfn.QUARTILE.INC(Cleaned_Data!E2:E250,3) -> 25 | L4: =K4-J4 -> 3 | M4: =F4/C4*100 -> 9.4349745
A5: study_hours_week | B5: =COUNT(Cleaned_Data!F2:F250) -> 249 | C5: =AVERAGE(Cleaned_Data!F2:F250) -> 16.29454 | D5: =MEDIAN(Cleaned_Data!F2:F250) -> 16.526721 | E5: =_xlfn.MODE.SNGL(Cleaned_Data!F2:F250) -> 16.526721 | F5: =_xlfn.STDEV.S(Cleaned_Data!F2:F250) -> 5.2618741 | G5: =MIN(Cleaned_Data!F2:F250) -> 2 | H5: =MAX(Cleaned_Data!F2:F250) -> 27.8 | I5: =H5-G5 -> 25.8 | J5: =_xlfn.QUARTILE.INC(Cleaned_Data!F2:F250,1) -> 12.8 | K5: =_xlfn.QUARTILE.INC(Cleaned_Data!F2:F250,3) -> 20.1 | L5: =K5-J5 -> 7.3 | M5: =F5/C5*100 -> 32.292253
A6: commute_minutes | B6: =COUNT(Cleaned_Data!G2:G250) -> 243 | C6: =AVERAGE(Cleaned_Data!G2:G250) -> 45.436214 | D6: =MEDIAN(Cleaned_Data!G2:G250) -> 33 | E6: =_xlfn.MODE.SNGL(Cleaned_Data!G2:G250) -> 37.2 | F6: =_xlfn.STDEV.S(Cleaned_Data!G2:G250) -> 40.151769 | G6: =MIN(Cleaned_Data!G2:G250) -> 5 | H6: =MAX(Cleaned_Data!G2:G250) -> 256.5 | I6: =H6-G6 -> 251.5 | J6: =_xlfn.QUARTILE.INC(Cleaned_Data!G2:G250,1) -> 19.95 | K6: =_xlfn.QUARTILE.INC(Cleaned_Data!G2:G250,3) -> 59.2 | L6: =K6-J6 -> 39.25 | M6: =F6/C6*100 -> 88.36953
A7: sleep_hours | B7: =COUNT(Cleaned_Data!H2:H250) -> 249 | C7: =AVERAGE(Cleaned_Data!H2:H250) -> 6.8309237 | D7: =MEDIAN(Cleaned_Data!H2:H250) -> 6.8 | E7: =_xlfn.MODE.SNGL(Cleaned_Data!H2:H250) -> 6.8 | F7: =_xlfn.STDEV.S(Cleaned_Data!H2:H250) -> 1.0718011 | G7: =MIN(Cleaned_Data!H2:H250) -> 3.8 | H7: =MAX(Cleaned_Data!H2:H250) -> 9.5 | I7: =H7-G7 -> 5.7 | J7: =_xlfn.QUARTILE.INC(Cleaned_Data!H2:H250,1) -> 6.1 | K7: =_xlfn.QUARTILE.INC(Cleaned_Data!H2:H250,3) -> 7.5 | L7: =K7-J7 -> 1.4 | M7: =F7/C7*100 -> 15.690427
A8: projects_submitted | B8: =COUNT(Cleaned_Data!H2:H250) -> 249 | C8: =AVERAGE(Cleaned_Data!I2:I250) -> 3.1485944 | D8: =MEDIAN(Cleaned_Data!I2:I250) -> 3 | E8: =_xlfn.MODE.SNGL(Cleaned_Data!I2:I250) -> 2 | F8: =_xlfn.STDEV.S(Cleaned_Data!I2:I250) -> 1.7909968 | G8: =MIN(Cleaned_Data!I2:I250) -> 0 | H8: =MAX(Cleaned_Data!I2:I250) -> 8 | I8: =H8-G8 -> 8 | J8: =_xlfn.QUARTILE.INC(Cleaned_Data!I2:I250,1) -> 2 | K8: =_xlfn.QUARTILE.INC(Cleaned_Data!I2:I250,3) -> 4 | L8: =K8-J8 -> 2 | M8: =F8/C8*100 -> 56.882423
A9: satisfaction_1to5 | B9: =COUNT(Cleaned_Data!H2:H250) -> 249 | C9: =AVERAGE(Cleaned_Data!J2:J250) -> 3.6064257 | D9: =MEDIAN(Cleaned_Data!J2:J250) -> 4 | E9: =_xlfn.MODE.SNGL(Cleaned_Data!J2:J250) -> 4 | F9: =_xlfn.STDEV.S(Cleaned_Data!J2:J250) -> 0.99884958 | G9: =MIN(Cleaned_Data!J2:J250) -> 1 | H9: =MAX(Cleaned_Data!J2:J250) -> 5 | I9: =H9-G9 -> 4 | J9: =_xlfn.QUARTILE.INC(Cleaned_Data!J2:J250,1) -> 3 | K9: =_xlfn.QUARTILE.INC(Cleaned_Data!J2:J250,3) -> 4 | L9: =K9-J9 -> 1 | M9: =F9/C9*100 -> 27.696386
A10: pets_at_home | B10: =COUNT(Cleaned_Data!M2:M250) -> 249 | C10: =AVERAGE(Cleaned_Data!M2:M250) -> 0.70682731 | D10: =MEDIAN(Cleaned_Data!M2:M250) -> 0 | E10: =_xlfn.MODE.SNGL(Cleaned_Data!M2:M250) -> 0 | F10: =_xlfn.STDEV.S(Cleaned_Data!M2:M250) -> 1.0072287 | G10: =MIN(Cleaned_Data!M2:M250) -> 0 | H10: =MAX(Cleaned_Data!M2:M250) -> 4 | I10: =H10-G10 -> 4 | J10: =_xlfn.QUARTILE.INC(Cleaned_Data!M2:M250,1) -> 0 | K10: =_xlfn.QUARTILE.INC(Cleaned_Data!M2:M250,3) -> 1 | L10: =K10-J10 -> 1 | M10: =F10/C10*100 -> 142.49997
A11: final_score | B11: =COUNT(Cleaned_Data!O2:O250) -> 249 | C11: =AVERAGE(Cleaned_Data!O2:O250) -> 79.309916 | D11: =MEDIAN(Cleaned_Data!O2:O250) -> 78.6 | E11: =_xlfn.MODE.SNGL(Cleaned_Data!O2:O250) -> 74.3 | F11: =_xlfn.STDEV.S(Cleaned_Data!O2:O250) -> 9.7682204 | G11: =MIN(Cleaned_Data!O2:O250) -> 50.4 | H11: =MAX(Cleaned_Data!O2:O250) -> 100 | I11: =H11-G11 -> 49.6 | J11: =_xlfn.QUARTILE.INC(Cleaned_Data!O2:O250,1) -> 72.7 | K11: =_xlfn.QUARTILE.INC(Cleaned_Data!O2:O250,3) -> 85.9 | L11: =K11-J11 -> 13.2 | M11: =F11/C11*100 -> 12.316518
